I'm sorry, but an uncaught exception occurred.

While running game code:
  File "game/script.rpy", line 31, in script
    ai "Слухи разжигают любопытство в людях"
Exception: Sayer 'ai' is not defined.

-- Full Traceback ------------------------------------------------------------

Full traceback:
  File "game/script.rpy", line 31, in script
    ai "Слухи разжигают любопытство в людях"
  File "D:\all\all_packs\Portable приложения\renpy-8.2.1-sdk\renpy\ast.py", line 2557, in execute
    Say.execute(self)
  File "D:\all\all_packs\Portable приложения\renpy-8.2.1-sdk\renpy\ast.py", line 575, in execute
    who = eval_who(self.who, self.who_fast)
  File "D:\all\all_packs\Portable приложения\renpy-8.2.1-sdk\renpy\ast.py", line 464, in eval_who
    raise Exception("Sayer '%s' is not defined." % who)
Exception: Sayer 'ai' is not defined.

Windows-10-10.0.19045 AMD64
Ren'Py 8.2.1.24030407
Seishinaku High School Mysteries 0.3_Choices
Thu May  2 00:50:39 2024
